<?xml version="1.0" encoding="UTF-8"?>
<!-- Generated by org.testng.reporters.JUnitReportReporter -->
<testsuite hostname="DESKTOP-2E2I19P" failures="1" tests="3" name="FeatureOne.Scenario2" time="9.357" errors="0" timestamp="2022-08-20T03:28:50 PDT" skipped="0">
  <testcase classname="FeatureOne.Scenario2" name="FileDownload" time="4.204"/>
  <system-out/>
  <testcase classname="FeatureOne.Scenario2" name="ExitIntent" time="4.420">
    <failure message="The following asserts failed:
	expected [false] but found [true]" type="java.lang.AssertionError">
      <![CDATA[java.lang.AssertionError: The following asserts failed:
expected [false] but found [true]
at org.testng.asserts.SoftAssert.assertAll(SoftAssert.java:46)
at org.testng.asserts.SoftAssert.assertAll(SoftAssert.java:30)
at FeatureOne.Scenario2.ExitIntent(Scenario2.java:77)
at java.base/jdk.internal.reflect.DirectMethodHandleAccessor.invoke(DirectMethodHandleAccessor.java:104)
at java.base/java.lang.reflect.Method.invoke(Method.java:577)
at org.testng.internal.invokers.MethodInvocationHelper.invokeMethod(MethodInvocationHelper.java:135)
at org.testng.internal.invokers.TestInvoker.invokeMethod(TestInvoker.java:673)
at org.testng.internal.invokers.TestInvoker.invokeTestMethod(TestInvoker.java:220)
at org.testng.internal.invokers.MethodRunner.runInSequence(MethodRunner.java:50)
at org.testng.internal.invokers.TestInvoker$MethodInvocationAgent.invoke(TestInvoker.java:945)
at org.testng.internal.invokers.TestInvoker.invokeTestMethods(TestInvoker.java:193)
at org.testng.internal.invokers.TestMethodWorker.invokeTestMethods(TestMethodWorker.java:146)
at org.testng.internal.invokers.TestMethodWorker.run(TestMethodWorker.java:128)
at java.base/java.util.ArrayList.forEach(ArrayList.java:1511)
at org.testng.TestRunner.privateRun(TestRunner.java:808)
at org.testng.TestRunner.run(TestRunner.java:603)
at org.testng.SuiteRunner.runTest(SuiteRunner.java:429)
at org.testng.SuiteRunner.runSequentially(SuiteRunner.java:423)
at org.testng.SuiteRunner.privateRun(SuiteRunner.java:383)
at org.testng.SuiteRunner.run(SuiteRunner.java:326)
at org.testng.SuiteRunnerWorker.runSuite(SuiteRunnerWorker.java:52)
at org.testng.SuiteRunnerWorker.run(SuiteRunnerWorker.java:95)
at org.testng.TestNG.runSuitesSequentially(TestNG.java:1249)
at org.testng.TestNG.runSuitesLocally(TestNG.java:1169)
at org.testng.TestNG.runSuites(TestNG.java:1092)
at org.testng.TestNG.run(TestNG.java:1060)
at org.apache.maven.surefire.testng.TestNGExecutor.run(TestNGExecutor.java:151)
at org.apache.maven.surefire.testng.TestNGDirectoryTestSuite.executeMulti(TestNGDirectoryTestSuite.java:192)
at org.apache.maven.surefire.testng.TestNGDirectoryTestSuite.execute(TestNGDirectoryTestSuite.java:93)
at org.apache.maven.surefire.testng.TestNGProvider.invoke(TestNGProvider.java:155)
at org.apache.maven.surefire.booter.ForkedBooter.runSuitesInProcess(ForkedBooter.java:456)
at org.apache.maven.surefire.booter.ForkedBooter.execute(ForkedBooter.java:169)
at org.apache.maven.surefire.booter.ForkedBooter.run(ForkedBooter.java:595)
at org.apache.maven.surefire.booter.ForkedBooter.main(ForkedBooter.java:581)
]]>
    </failure>
  </testcase> <!-- ExitIntent -->
  <system-out/>
  <testcase classname="FeatureOne.Scenario2" name="EntryAdd" time="0.733"/>
  <system-out/>
</testsuite> <!-- FeatureOne.Scenario2 -->
